Workbook

Sheet Grafische Darstellung
B2: Datum | E2: Andreas | F2: Hannes | G2: Noah | H2: Johannes Paul III
B3: 46023 | E3: 0 | F3: 0 | G3: 0 | H3: 0
B4: 46034 | C4: ='2026'!H9 -> 0.5 | D4: =IF(ISNUMBER(C4),C4,0) -> 0.5 | E4: =E3+'2026'!H9 -> 0.5 | F4: =F3+'2026'!L9 -> 0.5 | G4: =G3+'2026'!P9 -> 0 | H4: =H3+'2026'!T9 -> 0
B5: 46035 | C5: ='2026'!#REF! -> #REF! | D5: =IF(ISNUMBER(C5),C5,0) -> 0 | E5: =E4+'2026'!H10 -> 0.5 | F5: =F4+'2026'!L10 -> 0.5 | G5: =G4+'2026'!P10 -> 0 | H5: =H4+'2026'!T10 -> 0
B6: 46036 | C6: ='2026'!#REF! -> #REF! | D6: =IF(ISNUMBER(C6),C6,0) -> 0 | E6: =E5+'2026'!H11 -> 1.5 | F6: =F5+'2026'!L11 -> 0.5 | G6: =G5+'2026'!P11 -> 0 | H6: =H5+'2026'!T11 -> 0
B7: 46037 | C7: ='2026'!#REF! -> #REF! | D7: =IF(ISNUMBER(C7),C7,0) -> 0 | E7: =E6+'2026'!H12 -> 1.5 | F7: =F6+'2026'!L12 -> 0.5 | G7: =G6+'2026'!P12 -> 0.5 | H7: =H6+'2026'!T12 -> 1
B8: 46038 | C8: ='2026'!#REF! -> #REF! | D8: =IF(ISNUMBER(C8),C8,0) -> 0 | E8: =E7+'2026'!H13 -> 3 | F8: =F7+'2026'!L13 -> 0.5 | G8: =G7+'2026'!P13 -> 0.5 | H8: =H7+'2026'!T13 -> 1
B9: 46041 | C9: ='2026'!#REF! -> #REF! | D9: =IF(ISNUMBER(C9),C9,0) -> 0 | E9: =E8+'2026'!H14 -> 3.5 | F9: =F8+'2026'!L14 -> 1.5 | G9: =G8+'2026'!P14 -> 1.5 | H9: =H8+'2026'!T14 -> 1
B10: 46042 | C10: ='2026'!#REF! -> #REF! | D10: =IF(ISNUMBER(C10),C10,0) -> 0 | E10: =E9+'2026'!H15 -> 4.5 | F10: =F9+'2026'!L15 -> 2.5 | G10: =G9+'2026'!P15 -> 1.5 | H10: =H9+'2026'!T15 -> 2
B11: 46043 | C11: ='2026'!#REF! -> #REF! | D11: =IF(ISNUMBER(C11),C11,0) -> 0 | E11: =E10+'2026'!H16 -> 4.5 | F11: =F10+'2026'!L16 -> 2.5 | G11: =G10+'2026'!P16 -> 2 | H11: =H10+'2026'!T16 -> 2
B12: 46044 | C12: ='2026'!#REF! -> #REF! | D12: =IF(ISNUMBER(C12),C12,0) -> 0 | E12: =E11+'2026'!H17 -> 5.5 | F12: =F11+'2026'!L17 -> 3.5 | G12: =G11+'2026'!P17 -> 2 | H12: =H11+'2026'!T17 -> 2
B13: 46045 | C13: ='2026'!#REF! -> #REF! | D13: =IF(ISNUMBER(C13),C13,0) -> 0 | E13: =E12+'2026'!H18 -> 5.5 | F13: =F12+'2026'!L18 -> 3.5 | G13: =G12+'2026'!P18 -> 2 | H13: =H12+'2026'!T18 -> 2
B14: 46048 | C14: ='2026'!#REF! -> #REF! | D14: =IF(ISNUMBER(C14),C14,0) -> 0 | E14: =E13+'2026'!H19 -> 5.5 | F14: =F13+'2026'!L19 -> 3.5 | G14: =G13+'2026'!P19 -> 3.5 | H14: =H13+'2026'!T19 -> 2
B15: 46049 | C15: ='2026'!#REF! -> #REF! | D15: =IF(ISNUMBER(C15),C15,0) -> 0 | E15: =E14+'2026'!H20 -> 5.5 | F15: =F14+'2026'!L20 -> 3.5 | G15: =G14+'2026'!P20 -> 3.5 | H15: =H14+'2026'!T20 -> 2
B16: 46050 | C16: ='2026'!#REF! -> #REF! | D16: =IF(ISNUMBER(C16),C16,0) -> 0 | E16: =E15+'2026'!H21 -> 5.5 | F16: =F15+'2026'!L21 -> 3.5 | G16: =G15+'2026'!P21 -> 3.5 | H16: =H15+'2026'!T21 -> 2
... B224: 46342 | C224: ='2026'!#REF! -> #REF! | D224: =IF(ISNUMBER(C224),C224,0) -> 0 | E224: =E223+'2026'!H229 -> 44.5 | F224: =F223+'2026'!L229 -> 45.5 | G224: =G223+'2026'!P229 -> 41.5 | H224: =H223+'2026'!T229 -> 41
B225: 46343 | E225: =E224+'2026'!H230 -> 44.5 | F225: =F224+'2026'!L230 -> 45.5 | G225: =G224+'2026'!P230 -> 41.5 | H225: =H224+'2026'!T230 -> 41
B226: 46344 | E226: =E225+'2026'!H231 -> 44.5 | F226: =F225+'2026'!L231 -> 45.5 | G226: =G225+'2026'!P231 -> 41.5 | H226: =H225+'2026'!T231 -> 41
B227: 46345 | E227: =E226+'2026'!H232 -> 44.5 | F227: =F226+'2026'!L232 -> 45.5 | G227: =G226+'2026'!P232 -> 41.5 | H227: =H226+'2026'!T232 -> 41
B228: 46346 | E228: =E227+'2026'!H233 -> 44.5 | F228: =F227+'2026'!L233 -> 45.5 | G228: =G227+'2026'!P233 -> 41.5 | H228: =H227+'2026'!T233 -> 41
B229: 46349 | E229: =E228+'2026'!H234 -> 44.5 | F229: =F228+'2026'!L234 -> 45.5 | G229: =G228+'2026'!P234 -> 41.5 | H229: =H228+'2026'!T234 -> 41
B230: 46350 | E230: =E229+'2026'!H235 -> 44.5 | F230: =F229+'2026'!L235 -> 45.5 | G230: =G229+'2026'!P235 -> 41.5 | H230: =H229+'2026'!T235 -> 41
B231: 46351 | E231: =E230+'2026'!H236 -> 44.5 | F231: =F230+'2026'!L236 -> 45.5 | G231: =G230+'2026'!P236 -> 41.5 | H231: =H230+'2026'!T236 -> 41
B232: 46352 | E232: =E231+'2026'!H237 -> 44.5 | F232: =F231+'2026'!L237 -> 45.5 | G232: =G231+'2026'!P237 -> 41.5 | H232: =H231+'2026'!T237 -> 41
B233: 46353 | E233: =E232+'2026'!H238 -> 44.5 | F233: =F232+'2026'!L238 -> 45.5 | G233: =G232+'2026'!P238 -> 41.5 | H233: =H232+'2026'!T238 -> 41
B234: 46356 | E234: =E233+'2026'!H239 -> 44.5 | F234: =F233+'2026'!L239 -> 45.5 | G234: =G233+'2026'!P239 -> 41.5 | H234: =H233+'2026'!T239 -> 41
B235: 46357 | E235: =E234+'2026'!H240 -> 44.5 | F235: =F234+'2026'!L240 -> 45.5 | G235: =G234+'2026'!P240 -> 41.5 | H235: =H234+'2026'!T240 -> 41
B236: 46358 | E236: =E235+'2026'!H241 -> 44.5 | F236: =F235+'2026'!L241 -> 45.5 | G236: =G235+'2026'!P241 -> 41.5 | H236: =H235+'2026'!T241 -> 41
... B251: 46379 | E251: =E250+'2026'!H256 -> 44.5 | F251: =F250+'2026'!L256 -> 45.5 | G251: =G250+'2026'!P256 -> 41.5 | H251: =H250+'2026'!T256 -> 41

Sheet 2024
A1: Tag | B1: Vorspeise | C1: Hauptspeise | D1: Beilage | E1: Andreas | I1: Johannes | M1: Noah
E2: Vorspeise | F2: Hauptspeise | G2: Beilage | H2: Punkte | I2: Vorspeise | J2: Hauptspeise | K2: Beilage | L2: Punkte | M2: Vorspeise | N2: Hauptspeise | O2: Beilage | P2: Punkte
A3: 45590 | B3: Lasagne | C3: Bo | D3: Bo | E3: Lasagne | F3: Leberkas | G3: Röstkartoffeln | H3: =IF(ISBLANK($B3),$S$12,IF(AND($B3=E3,$C3=F3,$D3=G3),$S$9,IF(AND($B3=E3,OR($C3=F3,$D3=G3)),$S$10+$S$11,IF(OR($B3=E3,AND($C3=F3,$D3=G3)),$S$10,IF(OR($C3=F3,$D3=G3),$S$11))))) -> 1 | I3: Lasagne | J3: Truthahnbraten | K3: Spatzlen | L3: =IF(ISBLANK($B3),$S$12,IF(AND($B3=I3,$C3=J3,$D3=K3),$S$9,IF(AND($B3=I3,OR($C3=J3,$D3=K3)),$S$10+$S$11,IF(OR($B3=I3,AND($C3=J3,$D3=K3)),$S$10,IF(OR($C3=J3,$D3=K3),$S$11))))) -> 1 | M3: Spinatspatzlen | N3: Fisch | O3: Kartoffelsalat | P3: =IF(ISBLANK($B3),$S$12,IF(AND($B3=M3,$C3=N3,$D3=O3),$S$9,IF(AND($B3=M3,OR($C3=N3,$D3=O3)),$S$10+$S$11,IF(OR($B3=M3,AND($C3=N3,$D3=O3)),$S$10,IF(OR($C3=N3,$D3=O3),$S$11))))) -> FALSE
A4: 45593 | B4: Putanesca | C4: Schweinsschopf-braten | D4: Spatzlen | E4: Putanesca | F4: Schweinsschopf-braten | G4: Spatzlen | H4: =IF(ISBLANK($B4),$S$12,IF(AND($B4=E4,$C4=F4,$D4=G4),$S$9,IF(AND($B4=E4,OR($C4=F4,$D4=G4)),$S$10+$S$11,IF(OR($B4=E4,AND($C4=F4,$D4=G4)),$S$10,IF(OR($C4=F4,$D4=G4),$S$11))))) -> 3 | I4: Amatriciana | J4: Truthahn-geschnetzeltes | K4: Reis | L4: =IF(ISBLANK($B4),$S$12,IF(AND($B4=I4,$C4=J4,$D4=K4),$S$9,IF(AND($B4=I4,OR($C4=J4,$D4=K4)),$S$10+$S$11,IF(OR($B4=I4,AND($C4=J4,$D4=K4)),$S$10,IF(OR($C4=J4,$D4=K4),$S$11))))) -> FALSE | M4: Arrabbiata | N4: Truthahnschnitzel mit Champignonsauce | O4: Reis | P4: =IF(ISBLANK($B4),$S$12,IF(AND($B4=M4,$C4=N4,$D4=O4),$S$9,IF(AND($B4=M4,OR($C4=N4,$D4=O4)),$S$10+$S$11,IF(OR($B4=M4,AND($C4=N4,$D4=O4)),$S$10,IF(OR($C4=N4,$D4=O4),$S$11))))) -> FALSE
A5: 45594 | B5: Nudel Ragu | C5: Truthahnbraten | D5: Reis | E5: Knödel | F5: Pizzaioloschnitzel | G5: Ofenkartoffeln | H5: =IF(ISBLANK($B5),$S$12,IF(AND($B5=E5,$C5=F5,$D5=G5),$S$9,IF(AND($B5=E5,OR($C5=F5,$D5=G5)),$S$10+$S$11,IF(OR($B5=E5,AND($C5=F5,$D5=G5)),$S$10,IF(OR($C5=F5,$D5=G5),$S$11))))) -> FALSE | I5: - | J5: - | K5: - | L5: =IF(ISBLANK($B5),$S$12,IF(AND($B5=I5,$C5=J5,$D5=K5),$S$9,IF(AND($B5=I5,OR($C5=J5,$D5=K5)),$S$10+$S$11,IF(OR($B5=I5,AND($C5=J5,$D5=K5)),$S$10,IF(OR($C5=J5,$D5=K5),$S$11))))) -> FALSE | M5: Schlutzer | N5: Hühnerhaxlen | O5: Pommes | P5: =IF(ISBLANK($B5),$S$12,IF(AND($B5=M5,$C5=N5,$D5=O5),$S$9,IF(AND($B5=M5,OR($C5=N5,$D5=O5)),$S$10+$S$11,IF(OR($B5=M5,AND($C5=N5,$D5=O5)),$S$10,IF(OR($C5=N5,$D5=O5),$S$11))))) -> FALSE
A6: 45595 | B6: Pizza | C6: Leberkas | D6: Röstkartoffeln | E6: Schlutzer | F6: Gulasch | G6: Plent | H6: =IF(ISBLANK($B6),$S$12,IF(AND($B6=E6,$C6=F6,$D6=G6),$S$9,IF(AND($B6=E6,OR($C6=F6,$D6=G6)),$S$10+$S$11,IF(OR($B6=E6,AND($C6=F6,$D6=G6)),$S$10,IF(OR($C6=F6,$D6=G6),$S$11))))) -> FALSE | I6: - | J6: - | K6: - | L6: =IF(ISBLANK($B6),$S$12,IF(AND($B6=I6,$C6=J6,$D6=K6),$S$9,IF(AND($B6=I6,OR($C6=J6,$D6=K6)),$S$10+$S$11,IF(OR($B6=I6,AND($C6=J6,$D6=K6)),$S$10,IF(OR($C6=J6,$D6=K6),$S$11))))) -> FALSE | M6: Carbonara | N6: Hauswurst | O6: Kraut | P6: =IF(ISBLANK($B6),$S$12,IF(AND($B6=M6,$C6=N6,$D6=O6),$S$9,IF(AND($B6=M6,OR($C6=N6,$D6=O6)),$S$10+$S$11,IF(OR($B6=M6,AND($C6=N6,$D6=O6)),$S$10,IF(OR($C6=N6,$D6=O6),$S$11))))) -> FALSE
A7: 45596 | B7: Bo | C7: Wienerschnitzel | D7: Kartoffelsalat | E7: Nudel mit Käsesauce | F7: Hauswurst | G7: Kraut | H7: =IF(ISBLANK($B7),$S$12,IF(AND($B7=E7,$C7=F7,$D7=G7),$S$9,IF(AND($B7=E7,OR($C7=F7,$D7=G7)),$S$10+$S$11,IF(OR($B7=E7,AND($C7=F7,$D7=G7)),$S$10,IF(OR($C7=F7,$D7=G7),$S$11))))) -> FALSE | I7: - | J7: - | K7: - | L7: =IF(ISBLANK($B7),$S$12,IF(AND($B7=I7,$C7=J7,$D7=K7),$S$9,IF(AND($B7=I7,OR($C7=J7,$D7=K7)),$S$10+$S$11,IF(OR($B7=I7,AND($C7=J7,$D7=K7)),$S$10,IF(OR($C7=J7,$D7=K7),$S$11))))) -> FALSE | M7: Tortellini mit Ragu | N7: Truthahnschnitzel mit Champignonsauce | O7: Reis | P7: =IF(ISBLANK($B7),$S$12,IF(AND($B7=M7,$C7=N7,$D7=O7),$S$9,IF(AND($B7=M7,OR($C7=N7,$D7=O7)),$S$10+$S$11,IF(OR($B7=M7,AND($C7=N7,$D7=O7)),$S$10,IF(OR($C7=N7,$D7=O7),$S$11))))) -> FALSE
A8: 45607 | B8: Amatriciana | C8: Schweinsschopf-braten | D8: Reis | E8: Spinatspatzlen | F8: Truthahnschnitzel vom Grill | G8: Ofenkartoffeln | H8: =IF(ISBLANK($B8),$S$12,IF(AND($B8=E8,$C8=F8,$D8=G8),$S$9,IF(AND($B8=E8,OR($C8=F8,$D8=G8)),$S$10+$S$11,IF(OR($B8=E8,AND($C8=F8,$D8=G8)),$S$10,IF(OR($C8=F8,$D8=G8),$S$11))))) -> FALSE | I8: Hirten | J8: Truthahnbraten | K8: Pürree | L8: =IF(ISBLANK($B8),$S$12,IF(AND($B8=I8,$C8=J8,$D8=K8),$S$9,IF(AND($B8=I8,OR($C8=J8,$D8=K8)),$S$10+$S$11,IF(OR($B8=I8,AND($C8=J8,$D8=K8)),$S$10,IF(OR($C8=J8,$D8=K8),$S$11))))) -> FALSE | M8: Carbonara | N8: Truthahnschnitzel mit Champignonsauce | O8: Reis | P8: =IF(ISBLANK($B8),$S$12,IF(AND($B8=M8,$C8=N8,$D8=O8),$S$9,IF(AND($B8=M8,OR($C8=N8,$D8=O8)),$S$10+$S$11,IF(OR($B8=M8,AND($C8=N8,$D8=O8)),$S$10,IF(OR($C8=N8,$D8=O8),$S$11))))) -> 0.5
A9: 45608 | B9: Spinatspatzlen | C9: Truthahnbraten | D9: Pürree | E9: Nudel mit Käsesauce | F9: Truthahn-geschnetzeltes | G9: Reis | H9: =IF(ISBLANK($B9),$S$12,IF(AND($B9=E9,$C9=F9,$D9=G9),$S$9,IF(AND($B9=E9,OR($C9=F9,$D9=G9)),$S$10+$S$11,IF(OR($B9=E9,AND($C9=F9,$D9=G9)),$S$10,IF(OR($C9=F9,$D9=G9),$S$11))))) -> FALSE | I9: Spinatspatzlen | J9: Leberkas | K9: Röstkartoffeln | L9: =IF(ISBLANK($B9),$S$12,IF(AND($B9=I9,$C9=J9,$D9=K9),$S$9,IF(AND($B9=I9,OR($C9=J9,$D9=K9)),$S$10+$S$11,IF(OR($B9=I9,AND($C9=J9,$D9=K9)),$S$10,IF(OR($C9=J9,$D9=K9),$S$11))))) -> 1 | M9: Lasagne | N9: Leberkas | O9: Röstkartoffeln | P9: =IF(ISBLANK($B9),$S$12,IF(AND($B9=M9,$C9=N9,$D9=O9),$S$9,IF(AND($B9=M9,OR($C9=N9,$D9=O9)),$S$10+$S$11,IF(OR($B9=M9,AND($C9=N9,$D9=O9)),$S$10,IF(OR($C9=N9,$D9=O9),$S$11))))) -> FALSE | R9: Menü richtig | S9: 3
A10: 45609 | B10: Nudel mit Käsesauce | C10: Schweinskotelett | D10: Spatzlen | E10: Schlutzer | F10: Hauswurst | G10: Kraut | H10: =IF(ISBLANK($B10),$S$12,IF(AND($B10=E10,$C10=F10,$D10=G10),$S$9,IF(AND($B10=E10,OR($C10=F10,$D10=G10)),$S$10+$S$11,IF(OR($B10=E10,AND($C10=F10,$D10=G10)),$S$10,IF(OR($C10=F10,$D10=G10),$S$11))))) -> FALSE | I10: Knödel | J10: Schweinskotelett | K10: Pommes | L10: =IF(ISBLANK($B10),$S$12,IF(AND($B10=I10,$C10=J10,$D10=K10),$S$9,IF(AND($B10=I10,OR($C10=J10,$D10=K10)),$S$10+$S$11,IF(OR($B10=I10,AND($C10=J10,$D10=K10)),$S$10,IF(OR($C10=J10,$D10=K10),$S$11))))) -> 0.5 | M10: Carbonara | N10: Hauswurst | O10: Kraut | P10: =IF(ISBLANK($B10),$S$12,IF(AND($B10=M10,$C10=N10,$D10=O10),$S$9,IF(AND($B10=M10,OR($C10=N10,$D10=O10)),$S$10+$S$11,IF(OR($B10=M10,AND($C10=N10,$D10=O10)),$S$10,IF(OR($C10=N10,$D10=O10),$S$11))))) -> FALSE | R10: Hauptspeise mit Beilage / Vorspeise richtig | S10: 1
A11: 45610 | B11: Nudel mit Ragu | C11: Hühnerhaxlen | D11: Ofenkartoffeln | E11: Hirten | F11: Truthahnschnitzel vom Grill | G11: Ofenkartoffeln | H11: =IF(ISBLANK($B11),$S$12,IF(AND($B11=E11,$C11=F11,$D11=G11),$S$9,IF(AND($B11=E11,OR($C11=F11,$D11=G11)),$S$10+$S$11,IF(OR($B11=E11,AND($C11=F11,$D11=G11)),$S$10,IF(OR($C11=F11,$D11=G11),$S$11))))) -> 0.5 | I11: Gulaschsuppe | J11: Wienerschnitzel | K11: Kartoffelsalat | L11: =IF(ISBLANK($B11),$S$12,IF(AND($B11=I11,$C11=J11,$D11=K11),$S$9,IF(AND($B11=I11,OR($C11=J11,$D11=K11)),$S$10+$S$11,IF(OR($B11=I11,AND($C11=J11,$D11=K11)),$S$10,IF(OR($C11=J11,$D11=K11),$S$11))))) -> FALSE | M11: Tortellini mit Ragu | N11: Pizzaioloschnitzel | O11: Ofenkartoffeln | P11: =IF(ISBLANK($B11),$S$12,IF(AND($B11=M11,$C11=N11,$D11=O11),$S$9,IF(AND($B11=M11,OR($C11=N11,$D11=O11)),$S$10+$S$11,IF(OR($B11=M11,AND($C11=N11,$D11=O11)),$S$10,IF(OR($C11=N11,$D11=O11),$S$11))))) -> 0.5 | R11: nur Hauptspeise / Beilage richtig | S11: 0.5
A12: 45611 | B12: Spinatcannelloni | C12: Schweinsfilet | D12: Kroketten | E12: Ravioli mit Parmesan-Butter | F12: Leberkas | G12: Röstkartoffeln | H12: =IF(ISBLANK($B12),$S$12,IF(AND($B12=E12,$C12=F12,$D12=G12),$S$9,IF(AND($B12=E12,OR($C12=F12,$D12=G12)),$S$10+$S$11,IF(OR($B12=E12,AND($C12=F12,$D12=G12)),$S$10,IF(OR($C12=F12,$D12=G12),$S$11))))) -> FALSE | I12: Lasagne | J12: Sparerips | K12: Röstkartoffeln | L12: =IF(ISBLANK($B12),$S$12,IF(AND($B12=I12,$C12=J12,$D12=K12),$S$9,IF(AND($B12=I12,OR($C12=J12,$D12=K12)),$S$10+$S$11,IF(OR($B12=I12,AND($C12=J12,$D12=K12)),$S$10,IF(OR($C12=J12,$D12=K12),$S$11))))) -> FALSE | M12: Lasagne | N12: Truthahnschnitzel mit Champignonsauce | O12: Reis | P12: =IF(ISBLANK($B12),$S$12,IF(AND($B12=M12,$C12=N12,$D12=O12),$S$9,IF(AND($B12=M12,OR($C12=N12,$D12=O12)),$S$10+$S$11,IF(OR($B12=M12,AND($C12=N12,$D12=O12)),$S$10,IF(OR($C12=N12,$D12=O12),$S$11))))) -> FALSE | R12: Alles falsch | S12: 0
A13: 45614 | B13: Kürbisrisotto | C13: Truthahnschnitzel | D13: Ofenkartoffeln | E13: Hirten | F13: Fleischkarpfln | G13: Pürree | H13: =IF(ISBLANK($B13),$S$12,IF(AND($B13=E13,$C13=F13,$D13=G13),$S$9,IF(AND($B13=E13,OR($C13=F13,$D13=G13)),$S$10+$S$11,IF(OR($B13=E13,AND($C13=F13,$D13=G13)),$S$10,IF(OR($C13=F13,$D13=G13),$S$11))))) -> FALSE | I13: Hirten | J13: Knödel | K13: Gulasch | L13: =IF(ISBLANK($B13),$S$12,IF(AND($B13=I13,$C13=J13,$D13=K13),$S$9,IF(AND($B13=I13,OR($C13=J13,$D13=K13)),$S$10+$S$11,IF(OR($B13=I13,AND($C13=J13,$D13=K13)),$S$10,IF(OR($C13=J13,$D13=K13),$S$11))))) -> FALSE | M13: Hirten | N13: Hauswurst | O13: Plent | P13: =IF(ISBLANK($B13),$S$12,IF(AND($B13=M13,$C13=N13,$D13=O13),$S$9,IF(AND($B13=M13,OR($C13=N13,$D13=O13)),$S$10+$S$11,IF(OR($B13=M13,AND($C13=N13,$D13=O13)),$S$10,IF(OR($C13=N13,$D13=O13),$S$11))))) -> FALSE
A14: 45615 | B14: Hirten | C14: Paprika-Schweinegulasch | D14: Kartoffelstampf | E14: Speck-Zwiebelkuchen | F14: Truthahnbraten | G14: Reis | H14: =IF(ISBLANK($B14),$S$12,IF(AND($B14=E14,$C14=F14,$D14=G14),$S$9,IF(AND($B14=E14,OR($C14=F14,$D14=G14)),$S$10+$S$11,IF(OR($B14=E14,AND($C14=F14,$D14=G14)),$S$10,IF(OR($C14=F14,$D14=G14),$S$11))))) -> FALSE | I14: Spinatknödel | J14: Schweinsbraten | K14: Reis | L14: =IF(ISBLANK($B14),$S$12,IF(AND($B14=I14,$C14=J14,$D14=K14),$S$9,IF(AND($B14=I14,OR($C14=J14,$D14=K14)),$S$10+$S$11,IF(OR($B14=I14,AND($C14=J14,$D14=K14)),$S$10,IF(OR($C14=J14,$D14=K14),$S$11))))) -> FALSE | M14: Carbonara | N14: Leberkas | O14: Röstkartoffeln | P14: =IF(ISBLANK($B14),$S$12,IF(AND($B14=M14,$C14=N14,$D14=O14),$S$9,IF(AND($B14=M14,OR($C14=N14,$D14=O14)),$S$10+$S$11,IF(OR($B14=M14,AND($C14=N14,$D14=O14)),$S$10,IF(OR($C14=N14,$D14=O14),$S$11))))) -> FALSE
A15: 45616 | B15: Nudel mit Pesto | C15: Pizzaioloschnitzel | D15: Ofenkartoffeln | E15: Gnocchi | F15: Hauswurst | G15: Plent | H15: =IF(ISBLANK($B15),$S$12,IF(AND($B15=E15,$C15=F15,$D15=G15),$S$9,IF(AND($B15=E15,OR($C15=F15,$D15=G15)),$S$10+$S$11,IF(OR($B15=E15,AND($C15=F15,$D15=G15)),$S$10,IF(OR($C15=F15,$D15=G15),$S$11))))) -> FALSE | I15: Käseknödel | J15: Pizzaioloschnitzel | K15: Ofenkartoffeln | L15: =IF(ISBLANK($B15),$S$12,IF(AND($B15=I15,$C15=J15,$D15=K15),$S$9,IF(AND($B15=I15,OR($C15=J15,$D15=K15)),$S$10+$S$11,IF(OR($B15=I15,AND($C15=J15,$D15=K15)),$S$10,IF(OR($C15=J15,$D15=K15),$S$11))))) -> 1 | M15: Pizza | N15: Truthahnschnitzel mit Champignonsauce | O15: Reis | P15: =IF(ISBLANK($B15),$S$12,IF(AND($B15=M15,$C15=N15,$D15=O15),$S$9,IF(AND($B15=M15,OR($C15=N15,$D15=O15)),$S$10+$S$11,IF(OR($B15=M15,AND($C15=N15,$D15=O15)),$S$10,IF(OR($C15=N15,$D15=O15),$S$11))))) -> FALSE
A16: 45617 | B16: Nudel mit Tomatensoße und Mozzarella | C16: Gekochtes Rindfleisch | D16: Salzkartoffeln | E16: Lasagne | F16: Wienerschnitzel | G16: Pommes | H16: =IF(ISBLANK($B16),$S$12,IF(AND($B16=E16,$C16=F16,$D16=G16),$S$9,IF(AND($B16=E16,OR($C16=F16,$D16=G16)),$S$10+$S$11,IF(OR($B16=E16,AND($C16=F16,$D16=G16)),$S$10,IF(OR($C16=F16,$D16=G16),$S$11))))) -> FALSE | I16: Carbonara | J16: Leberkas | K16: Pommes | L16: =IF(ISBLANK($B16),$S$12,IF(AND($B16=I16,$C16=J16,$D16=K16),$S$9,IF(AND($B16=I16,OR($C16=J16,$D16=K16)),$S$10+$S$11,IF(OR($B16=I16,AND($C16=J16,$D16=K16)),$S$10,IF(OR($C16=J16,$D16=K16),$S$11))))) -> FALSE | M16: Putanesca | N16: Truthahnbraten | O16: Pürree | P16: =IF(ISBLANK($B16),$S$12,IF(AND($B16=M16,$C16=N16,$D16=O16),$S$9,IF(AND($B16=M16,OR($C16=N16,$D16=O16)),$S$10+$S$11,IF(OR($B16=M16,AND($C16=N16,$D16=O16)),$S$10,IF(OR($C16=N16,$D16=O16),$S$11))))) -> FALSE
A17: 45618 | B17: Käseknödel | C17: Ossobuchi | D17: Safranreis | E17: Tortellini Schinken-Rahm | F17: Leberkas | G17: Röstkartoffeln | H17: =IF(ISBLANK($B17),$S$12,IF(AND($B17=E17,$C17=F17,$D17=G17),$S$9,IF(AND($B17=E17,OR($C17=F17,$D17=G17)),$S$10+$S$11,IF(OR($B17=E17,AND($C17=F17,$D17=G17)),$S$10,IF(OR($C17=F17,$D17=G17),$S$11))))) -> FALSE | I17: Käseknödel | J17: Wienerschnitzel | K17: Kartoffelsalat | L17: =IF(ISBLANK($B17),$S$12,IF(AND($B17=I17,$C17=J17,$D17=K17),$S$9,IF(AND($B17=I17,OR($C17=J17,$D17=K17)),$S$10+$S$11,IF(OR($B17=I17,AND($C17=J17,$D17=K17)),$S$10,IF(OR($C17=J17,$D17=K17),$S$11))))) -> 1 | M17: Tortellini mit Ragu | N17: Fisch | O17: Kartoffelsalat | P17: =IF(ISBLANK($B17),$S$12,IF(AND($B17=M17,$C17=N17,$D17=O17),$S$9,IF(AND($B17=M17,OR($C17=N17,$D17=O17)),$S$10+$S$11,IF(OR($B17=M17,AND($C17=N17,$D17=O17)),$S$10,IF(OR($C17=N17,$D17=O17),$S$11))))) -> FALSE
A18: 45621 | B18: Nudel mit Thunfischsoße | C18: Schweinsschnitzel | D18: Pommes | E18: Lasagne | F18: Curry-Geschnetzeltes | G18: Reis | H18: =IF(ISBLANK($B18),$S$12,IF(AND($B18=E18,$C18=F18,$D18=G18),$S$9,IF(AND($B18=E18,OR($C18=F18,$D18=G18)),$S$10+$S$11,IF(OR($B18=E18,AND($C18=F18,$D18=G18)),$S$10,IF(OR($C18=F18,$D18=G18),$S$11))))) -> FALSE | I18: Carbonara | J18: Schweinsbraten | K18: Reis | L18: =IF(ISBLANK($B18),$S$12,IF(AND($B18=I18,$C18=J18,$D18=K18),$S$9,IF(AND($B18=I18,OR($C18=J18,$D18=K18)),$S$10+$S$11,IF(OR($B18=I18,AND($C18=J18,$D18=K18)),$S$10,IF(OR($C18=J18,$D18=K18),$S$11))))) -> FALSE | M18: Aglio olio | N18: Truthahnschnitzel mit Champignonsauce | O18: Reis | P18: =IF(ISBLANK($B18),$S$12,IF(AND($B18=M18,$C18=N18,$D18=O18),$S$9,IF(AND($B18=M18,OR($C18=N18,$D18=O18)),$S$10+$S$11,IF(OR($B18=M18,AND($C18=N18,$D18=O18)),$S$10,IF(OR($C18=N18,$D18=O18),$S$11))))) -> FALSE
A19: 45622 | B19: Gnocchi | C19: Hühnerbrust | D19: Reis | E19: Tortellini Schinken-Rahm | F19: Truthahnbraten | G19: Pürree | H19: =IF(ISBLANK($B19),$S$12,IF(AND($B19=E19,$C19=F19,$D19=G19),$S$9,IF(AND($B19=E19,OR($C19=F19,$D19=G19)),$S$10+$S$11,IF(OR($B19=E19,AND($C19=F19,$D19=G19)),$S$10,IF(OR($C19=F19,$D19=G19),$S$11))))) -> FALSE | I19: - | J19: - | K19: - | L19: =IF(ISBLANK($B19),$S$12,IF(AND($B19=I19,$C19=J19,$D19=K19),$S$9,IF(AND($B19=I19,OR($C19=J19,$D19=K19)),$S$10+$S$11,IF(OR($B19=I19,AND($C19=J19,$D19=K19)),$S$10,IF(OR($C19=J19,$D19=K19),$S$11))))) -> FALSE | M19: - | N19: - | O19: - | P19: =IF(ISBLANK($B19),$S$12,IF(AND($B19=M19,$C19=N19,$D19=O19),$S$9,IF(AND($B19=M19,OR($C19=N19,$D19=O19)),$S$10+$S$11,IF(OR($B19=M19,AND($C19=N19,$D19=O19)),$S$10,IF(OR($C19=N19,$D19=O19),$S$11))))) -> FALSE
A20: 45623 | B20: Aglio olio | C20: Schweinskotelett | D20: Spatzlen | E20: Spinatspatzlen | F20: Leberkas | G20: Röstkartoffeln | H20: =IF(ISBLANK($B20),$S$12,IF(AND($B20=E20,$C20=F20,$D20=G20),$S$9,IF(AND($B20=E20,OR($C20=F20,$D20=G20)),$S$10+$S$11,IF(OR($B20=E20,AND($C20=F20,$D20=G20)),$S$10,IF(OR($C20=F20,$D20=G20),$S$11))))) -> FALSE | I20: Hirten | J20: Knödel | K20: Gulasch | L20: =IF(ISBLANK($B20),$S$12,IF(AND($B20=I20,$C20=J20,$D20=K20),$S$9,IF(AND($B20=I20,OR($C20=J20,$D20=K20)),$S$10+$S$11,IF(OR($B20=I20,AND($C20=J20,$D20=K20)),$S$10,IF(OR($C20=J20,$D20=K20),$S$11))))) -> FALSE | M20: Carbonara | N20: Leberkas | O20: Röstkartoffeln | P20: =IF(ISBLANK($B20),$S$12,IF(AND($B20=M20,$C20=N20,$D20=O20),$S$9,IF(AND($B20=M20,OR($C20=N20,$D20=O20)),$S$10+$S$11,IF(OR($B20=M20,AND($C20=N20,$D20=O20)),$S$10,IF(OR($C20=N20,$D20=O20),$S$11))))) -> FALSE
A21: 45624 | B21: Schlutzer Schinken-Rahm | C21: Truthahnbraten | D21: Kroketten | E21: Lasagne | F21: Hühnerhaxlen | G21: Pommes | H21: =IF(ISBLANK($B21),$S$12,IF(AND($B21=E21,$C21=F21,$D21=G21),$S$9,IF(AND($B21=E21,OR($C21=F21,$D21=G21)),$S$10+$S$11,IF(OR($B21=E21,AND($C21=F21,$D21=G21)),$S$10,IF(OR($C21=F21,$D21=G21),$S$11))))) -> FALSE | I21: - | J21: - | K21: - | L21: =IF(ISBLANK($B21),$S$12,IF(AND($B21=I21,$C21=J21,$D21=K21),$S$9,IF(AND($B21=I21,OR($C21=J21,$D21=K21)),$S$10+$S$11,IF(OR($B21=I21,AND($C21=J21,$D21=K21)),$S$10,IF(OR($C21=J21,$D21=K21),$S$11))))) -> FALSE | M21: Hirten | N21: Hauswurst | O21: Plent | P21: =IF(ISBLANK($B21),$S$12,IF(AND($B21=M21,$C21=N21,$D21=O21),$S$9,IF(AND($B21=M21,OR($C21=N21,$D21=O21)),$S$10+$S$11,IF(OR($B21=M21,AND($C21=N21,$D21=O21)),$S$10,IF(OR($C21=N21,$D21=O21),$S$11))))) -> FALSE
A22: 45625 | B22: Nudel mit Lachs und Tomantensoße | C22: Schweinshaxe | D22: Reis | E22: Carbonara | F22: Leberkas | G22: Röstkartoffeln | H22: =IF(ISBLANK($B22),$S$12,IF(AND($B22=E22,$C22=F22,$D22=G22),$S$9,IF(AND($B22=E22,OR($C22=F22,$D22=G22)),$S$10+$S$11,IF(OR($B22=E22,AND($C22=F22,$D22=G22)),$S$10,IF(OR($C22=F22,$D22=G22),$S$11))))) -> FALSE | I22: Putanesca | J22: Wienerschnitzel | K22: Kartoffelsalat | L22: =IF(ISBLANK($B22),$S$12,IF(AND($B22=I22,$C22=J22,$D22=K22),$S$9,IF(AND($B22=I22,OR($C22=J22,$D22=K22)),$S$10+$S$11,IF(OR($B22=I22,AND($C22=J22,$D22=K22)),$S$10,IF(OR($C22=J22,$D22=K22),$S$11))))) -> FALSE | M22: Lasagne | N22: Wienerschnitzel | O22: Kartoffelsalat | P22: =IF(ISBLANK($B22),$S$12,IF(AND($B22=M22,$C22=N22,$D22=O22),$S$9,IF(AND($B22=M22,OR($C22=N22,$D22=O22)),$S$10+$S$11,IF(OR($B22=M22,AND($C22=N22,$D22=O22)),$S$10,IF(OR($C22=N22,$D22=O22),$S$11))))) -> FALSE
A23: 45628 | B23: Arrabbiata | C23: Truthahnschnitzel mit Champignonsauce | D23: Reis | E23: Nudel mit Ragu | F23: Schweinsschopf-braten | G23: Spatzlen | H23: =IF(ISBLANK($B23),$S$12,IF(AND($B23=E23,$C23=F23,$D23=G23),$S$9,IF(AND($B23=E23,OR($C23=F23,$D23=G23)),$S$10+$S$11,IF(OR($B23=E23,AND($C23=F23,$D23=G23)),$S$10,IF(OR($C23=F23,$D23=G23),$S$11))))) -> FALSE | I23: Amatriciana | J23: Schweinsschnitzel | K23: Ofenkartoffeln | L23: =IF(ISBLANK($B23),$S$12,IF(AND($B23=I23,$C23=J23,$D23=K23),$S$9,IF(AND($B23=I23,OR($C23=J23,$D23=K23)),$S$10+$S$11,IF(OR($B23=I23,AND($C23=J23,$D23=K23)),$S$10,IF(OR($C23=J23,$D23=K23),$S$11))))) -> FALSE | M23: Hirten | N23: Hauswurst | O23: Plent | P23: =IF(ISBLANK($B23),$S$12,IF(AND($B23=M23,$C23=N23,$D23=O23),$S$9,IF(AND($B23=M23,OR($C23=N23,$D23=O23)),$S$10+$S$11,IF(OR($B23=M23,AND($C23=N23,$D23=O23)),$S$10,IF(OR($C23=N23,$D23=O23),$S$11))))) -> FALSE
A24: 45629 | B24: Fleischcannelloni | C24: Truthahngeschnetzeltes | D24: Pürree | E24: Spinatspatzlen | F24: Leberkas | G24: Röstkartoffeln | H24: =IF(ISBLANK($B24),$S$12,IF(AND($B24=E24,$C24=F24,$D24=G24),$S$9,IF(AND($B24=E24,OR($C24=F24,$D24=G24)),$S$10+$S$11,IF(OR($B24=E24,AND($C24=F24,$D24=G24)),$S$10,IF(OR($C24=F24,$D24=G24),$S$11))))) -> FALSE | I24: Carbonara | J24: Gekochtes Rindfleisch | K24: Salzkartoffel | L24: =IF(ISBLANK($B24),$S$12,IF(AND($B24=I24,$C24=J24,$D24=K24),$S$9,IF(AND($B24=I24,OR($C24=J24,$D24=K24)),$S$10+$S$11,IF(OR($B24=I24,AND($C24=J24,$D24=K24)),$S$10,IF(OR($C24=J24,$D24=K24),$S$11))))) -> FALSE | M24: Lasagne | N24: Pizzaioloschnitzel | O24: Ofenkartoffeln | P24: =IF(ISBLANK($B24),$S$12,IF(AND($B24=M24,$C24=N24,$D24=O24),$S$9,IF(AND($B24=M24,OR($C24=N24,$D24=O24)),$S$10+$S$11,IF(OR($B24=M24,AND($C24=N24,$D24=O24)),$S$10,IF(OR($C24=N24,$D24=O24),$S$11))))) -> FALSE
... A36: 45645 | B36: Lasagne | C36: Truthahngeschnetzeltes | D36: Spatzlen | E36: Lasagne | F36: Truthahngeschnetzeltes | G36: Pürree | H36: =IF(ISBLANK($B36),$S$12,IF(AND($B36=E36,$C36=F36,$D36=G36),$S$9,IF(AND($B36=E36,OR($C36=F36,$D36=G36)),$S$10+$S$11,IF(OR($B36=E36,AND($C36=F36,$D36=G36)),$S$10,IF(OR($C36=F36,$D36=G36),$S$11))))) -> 1.5 | I36: Käseknödel | J36: Wienerschnitzel | K36: Kartoffelsalat | L36: =IF(ISBLANK($B36),$S$12,IF(AND($B36=I36,$C36=J36,$D36=K36),$S$9,IF(AND($B36=I36,OR($C36=J36,$D36=K36)),$S$10+$S$11,IF(OR($B36=I36,AND($C36=J36,$D36=K36)),$S$10,IF(OR($C36=J36,$D36=K36),$S$11))))) -> FALSE | M36: - | N36: - | O36: - | P36: =IF(ISBLANK($B36),$S$12,IF(AND($B36=M36,$C36=N36,$D36=O36),$S$9,IF(AND($B36=M36,OR($C36=N36,$D36=O36)),$S$10+$S$11,IF(OR($B36=M36,AND($C36=N36,$D36=O36)),$S$10,IF(OR($C36=N36,$D36=O36),$S$11))))) -> FALSE
A37: 45646 | E37: Nudel mit Lachs und Rahmsoße | F37: Pfeffersteak | G37: Kartoffelstrudel | H37: =IF(ISBLANK($B37),$S$12,IF(AND($B37=E37,$C37=F37,$D37=G37),$S$9,IF(AND($B37=E37,OR($C37=F37,$D37=G37)),$S$10+$S$11,IF(OR($B37=E37,AND($C37=F37,$D37=G37)),$S$10,IF(OR($C37=F37,$D37=G37),$S$11))))) -> 0 | I37: Hirten | J37: Fischfilet | K37: Salzkartoffel | L37: =IF(ISBLANK($B37),$S$12,IF(AND($B37=I37,$C37=J37,$D37=K37),$S$9,IF(AND($B37=I37,OR($C37=J37,$D37=K37)),$S$10+$S$11,IF(OR($B37=I37,AND($C37=J37,$D37=K37)),$S$10,IF(OR($C37=J37,$D37=K37),$S$11))))) -> 0 | M37: Nudel mit Meeresfrüchten | N37: Rindsschnitzel | O37: Ofenkartoffeln | P37: =IF(ISBLANK($B37),$S$12,IF(AND($B37=M37,$C37=N37,$D37=O37),$S$9,IF(AND($B37=M37,OR($C37=N37,$D37=O37)),$S$10+$S$11,IF(OR($B37=M37,AND($C37=N37,$D37=O37)),$S$10,IF(OR($C37=N37,$D37=O37),$S$11))))) -> 0
A38: Ergebnisse | E38: Summe | H38: =SUM(H3:H37) -> 6.5 | I38: Summe | L38: =SUM(L3:L37) -> 6 | M38: Summe | P38: =SUM(P3:P37) -> 3
E39: Alles Falsch | H39: =COUNTIF(H2:H37,"Falsch") -> 29 | I39: Alles Falsch | L39: =COUNTIF(L2:L37,"Falsch") -> 27 | M39: Alles Falsch | P39: =COUNTIF(P2:P37,"Falsch") -> 29
E40: Alles Richtig | H40: =COUNTIF(H3:H37,"3") -> 1 | I40: Alles Richtig | L40: =COUNTIF(L3:L37,"3") -> 0 | M40: Alles Richtig | P40: =COUNTIF(P3:P37,"3") -> 0

Sheet 2025
A1: Tippspiel Essen Wies | E1: Andreas | I1: Johannes | M1: Noah
A3: Regelwerk siehe entsprechendes Tabellenblatt | E3: Punkte | H3: =SUM(H9:H229) -> 47 | I3: Punkte | L3: =SUM(L9:L229) -> 42.5 | M3: Punkte | P3: =SUM(P9:P229) -> 51.5
E4: Punkteausbeute | H4: =(100/(3*COUNTIF($A$9:$A$229,"<>")))*H3 -> 7.0889894 | I4: Punkteausbeute | L4: =(100/(3*COUNTIF($A$9:$A$229,"<>")))*L3 -> 6.4102564 | M4: Punkteausbeute | P4: =(100/(3*COUNTIF($A$9:$A$229,"<>")))*P3 -> 7.7677225
E5: Alles Falsch | H5: =COUNTIF(H9:H229,"Falsch") -> 160 | I5: Alles Falsch | L5: =COUNTIF(L9:L229,"Falsch") -> 169 | M5: Alles Falsch | P5: =COUNTIF(P9:P229,"Falsch") -> 158
H6: =(100/COUNTIF($A$9:$A$229,"<>"))*H5 -> 72.39819 | L6: =(100/COUNTIF($A$9:$A$229,"<>"))*L5 -> 76.470588 | P6: =(100/COUNTIF($A$9:$A$229,"<>"))*P5 -> 71.493213
E7: Alles Richtig | H7: =COUNTIF(H9:H229,"3") -> 1 | I7: Alles Richtig | L7: =COUNTIF(L9:L229,"3")-1 -> 1 | M7: Alles Richtig | P7: =COUNTIF(P9:P229,"3") -> 1
A8: Tag | B8: Vorspeise | C8: Hauptspeise | D8: Beilage | E8: Vorspeise | F8: Hauptspeise | G8: Beilage | H8: Punkte | I8: Vorspeise | J8: Hauptspeise | K8: Beilage | L8: Punkte | M8: Vorspeise | N8: Hauptspeise | O8: Beilage | P8: Punkte
A9: 45670 | B9: Arrabbiata | C9: Truthahnschnitzel | D9: Reis | E9: Spinatspatzlen | F9: Schweinskotelett | G9: Ofenkartoffeln | H9: =IF(ISBLANK($B9),$S$18,IF(AND($B9=E9,$C9=F9,$D9=G9),$S$15,IF(AND($B9=E9,OR($C9=F9,$D9=G9)),$S$16+$S$17,IF(OR($B9=E9,AND($C9=F9,$D9=G9)),$S$16,IF(OR($C9=F9,$D9=G9),$S$17))))) -> FALSE | I9: Hirten | J9: Truthahnschnitzel | K9: Pommes | L9: =IF(ISBLANK($B9),$S$18,IF(AND($B9=I9,$C9=J9,$D9=K9),$S$15,IF(AND($B9=I9,OR($C9=J9,$D9=K9)),$S$16+$S$17,IF(OR($B9=I9,AND($C9=J9,$D9=K9)),$S$16,IF(OR($C9=J9,$D9=K9),$S$17))))) -> 0.5 | M9: Hirten | N9: Truthahnschnitzel | O9: Reis | P9: =IF(ISBLANK($B9),$S$18,IF(AND($B9=M9,$C9=N9,$D9=O9),$S$15,IF(AND($B9=M9,OR($C9=N9,$D9=O9)),$S$16+$S$17,IF(OR($B9=M9,AND($C9=N9,$D9=O9)),$S$16,IF(OR($C9=N9,$D9=O9),$S$17))))) -> 1
A10: 45671 | B10: Nudel mit Käsesoße | C10: Leberkas | D10: Pommes | E10: Nudel mit Käsesoße | F10: Fleischkrapfln | G10: Püree | H10: =IF(ISBLANK($B10),$S$18,IF(AND($B10=E10,$C10=F10,$D10=G10),$S$15,IF(AND($B10=E10,OR($C10=F10,$D10=G10)),$S$16+$S$17,IF(OR($B10=E10,AND($C10=F10,$D10=G10)),$S$16,IF(OR($C10=F10,$D10=G10),$S$17))))) -> 1 | I10: Käseknödel | J10: Schweinsbraten | K10: Püree | L10: =IF(ISBLANK($B10),$S$18,IF(AND($B10=I10,$C10=J10,$D10=K10),$S$15,IF(AND($B10=I10,OR($C10=J10,$D10=K10)),$S$16+$S$17,IF(OR($B10=I10,AND($C10=J10,$D10=K10)),$S$16,IF(OR($C10=J10,$D10=K10),$S$17))))) -> FALSE | M10: Lasagne | N10: Schweinskotelett | O10: Spatzlen | P10: =IF(ISBLANK($B10),$S$18,IF(AND($B10=M10,$C10=N10,$D10=O10),$S$15,IF(AND($B10=M10,OR($C10=N10,$D10=O10)),$S$16+$S$17,IF(OR($B10=M10,AND($C10=N10,$D10=O10)),$S$16,IF(OR($C10=N10,$D10=O10),$S$17))))) -> FALSE
A11: 45672 | B11: Omlett mit Schinken und Käse | C11: Schweinskotelett | D11: Bratkartoffeln | E11: Tortellini mit Schinken-Rahm | F11: Schweinsschopfbraten | G11: Spatzlen | H11: =IF(ISBLANK($B11),$S$18,IF(AND($B11=E11,$C11=F11,$D11=G11),$S$15,IF(AND($B11=E11,OR($C11=F11,$D11=G11)),$S$16+$S$17,IF(OR($B11=E11,AND($C11=F11,$D11=G11)),$S$16,IF(OR($C11=F11,$D11=G11),$S$17))))) -> FALSE | I11: Carbonara | J11: Knödel | K11: Gulasch | L11: =IF(ISBLANK($B11),$S$18,IF(AND($B11=I11,$C11=J11,$D11=K11),$S$15,IF(AND($B11=I11,OR($C11=J11,$D11=K11)),$S$16+$S$17,IF(OR($B11=I11,AND($C11=J11,$D11=K11)),$S$16,IF(OR($C11=J11,$D11=K11),$S$17))))) -> FALSE | M11: Nudel mit Ragu | N11: Truthahnbraten | O11: Püree | P11: =IF(ISBLANK($B11),$S$18,IF(AND($B11=M11,$C11=N11,$D11=O11),$S$15,IF(AND($B11=M11,OR($C11=N11,$D11=O11)),$S$16+$S$17,IF(OR($B11=M11,AND($C11=N11,$D11=O11)),$S$16,IF(OR($C11=N11,$D11=O11),$S$17))))) -> FALSE
A12: 45673 | B12: Aglio olio | C12: Hühnerbrust | D12: Kroketten und Zucchini | E12: Lasagne | F12: Pizzaioloschnitzel | G12: Ofenkartoffeln | H12: =IF(ISBLANK($B12),$S$18,IF(AND($B12=E12,$C12=F12,$D12=G12),$S$15,IF(AND($B12=E12,OR($C12=F12,$D12=G12)),$S$16+$S$17,IF(OR($B12=E12,AND($C12=F12,$D12=G12)),$S$16,IF(OR($C12=F12,$D12=G12),$S$17))))) -> FALSE | I12: Hirten | J12: Schweinsbraten | K12: Püree | L12: =IF(ISBLANK($B12),$S$18,IF(AND($B12=I12,$C12=J12,$D12=K12),$S$15,IF(AND($B12=I12,OR($C12=J12,$D12=K12)),$S$16+$S$17,IF(OR($B12=I12,AND($C12=J12,$D12=K12)),$S$16,IF(OR($C12=J12,$D12=K12),$S$17))))) -> FALSE | M12: Carbonara | N12: Knödel | O12: Gulasch | P12: =IF(ISBLANK($B12),$S$18,IF(AND($B12=M12,$C12=N12,$D12=O12),$S$15,IF(AND($B12=M12,OR($C12=N12,$D12=O12)),$S$16+$S$17,IF(OR($B12=M12,AND($C12=N12,$D12=O12)),$S$16,IF(OR($C12=N12,$D12=O12),$S$17))))) -> FALSE
A13: 45674 | B13: Schupfnudel mit Lachs | C13: Hauswurst | D13: Plent | E13: Spinatcannelloni | F13: Wienerschnitzel | G13: Kartoffelsalat | H13: =IF(ISBLANK($B13),$S$18,IF(AND($B13=E13,$C13=F13,$D13=G13),$S$15,IF(AND($B13=E13,OR($C13=F13,$D13=G13)),$S$16+$S$17,IF(OR($B13=E13,AND($C13=F13,$D13=G13)),$S$16,IF(OR($C13=F13,$D13=G13),$S$17))))) -> FALSE | I13: Käseknödel | J13: Wienerschnitzel | K13: Kartoffelsalat | L13: =IF(ISBLANK($B13),$S$18,IF(AND($B13=I13,$C13=J13,$D13=K13),$S$15,IF(AND($B13=I13,OR($C13=J13,$D13=K13)),$S$16+$S$17,IF(OR($B13=I13,AND($C13=J13,$D13=K13)),$S$16,IF(OR($C13=J13,$D13=K13),$S$17))))) -> FALSE | M13: Lasagne | N13: Gekochtes Rindfleisch | O13: Salzkartoffeln | P13: =IF(ISBLANK($B13),$S$18,IF(AND($B13=M13,$C13=N13,$D13=O13),$S$15,IF(AND($B13=M13,OR($C13=N13,$D13=O13)),$S$16+$S$17,IF(OR($B13=M13,AND($C13=N13,$D13=O13)),$S$16,IF(OR($C13=N13,$D13=O13),$S$17))))) -> FALSE
A14: 45677 | B14: Nudel mit Ragu | C14: Schweinsfilet | D14: Reis | E14: Hirten | F14: Truthahngeschnetzeltes | G14: Püree | H14: =IF(ISBLANK($B14),$S$18,IF(AND($B14=E14,$C14=F14,$D14=G14),$S$15,IF(AND($B14=E14,OR($C14=F14,$D14=G14)),$S$16+$S$17,IF(OR($B14=E14,AND($C14=F14,$D14=G14)),$S$16,IF(OR($C14=F14,$D14=G14),$S$17))))) -> FALSE | I14: Hirten | J14: Truthahnschnitzel | K14: Ofenkartoffeln | L14: =IF(ISBLANK($B14),$S$18,IF(AND($B14=I14,$C14=J14,$D14=K14),$S$15,IF(AND($B14=I14,OR($C14=J14,$D14=K14)),$S$16+$S$17,IF(OR($B14=I14,AND($C14=J14,$D14=K14)),$S$16,IF(OR($C14=J14,$D14=K14),$S$17))))) -> FALSE | M14: Carbonara | N14: Pizzaioloschnitzel | O14: Ofenkartoffeln | P14: =IF(ISBLANK($B14),$S$18,IF(AND($B14=M14,$C14=N14,$D14=O14),$S$15,IF(AND($B14=M14,OR($C14=N14,$D14=O14)),$S$16+$S$17,IF(OR($B14=M14,AND($C14=N14,$D14=O14)),$S$16,IF(OR($C14=N14,$D14=O14),$S$17))))) -> FALSE
A15: 45678 | B15: Gulaschsuppe + Nudel mit Käsesoße | C15: Gekochtes Rindfleisch | D15: Salzkartoffeln | E15: Tortellini mit Schinken-Rahm | F15: Gekochtes Rindfleisch | G15: Salzkartoffeln | H15: =IF(ISBLANK($B15),$S$18,IF(AND($B15=E15,$C15=F15,$D15=G15),$S$15,IF(AND($B15=E15,OR($C15=F15,$D15=G15)),$S$16+$S$17,IF(OR($B15=E15,AND($C15=F15,$D15=G15)),$S$16,IF(OR($C15=F15,$D15=G15),$S$17))))) -> 1 | I15: Lasagne | J15: Knödel | K15: Gulasch | L15: =IF(ISBLANK($B15),$S$18,IF(AND($B15=I15,$C15=J15,$D15=K15),$S$15,IF(AND($B15=I15,OR($C15=J15,$D15=K15)),$S$16+$S$17,IF(OR($B15=I15,AND($C15=J15,$D15=K15)),$S$16,IF(OR($C15=J15,$D15=K15),$S$17))))) -> FALSE | M15: Hirten | N15: Hühnerhaxl | O15: Bratkartoffeln | P15: =IF(ISBLANK($B15),$S$18,IF(AND($B15=M15,$C15=N15,$D15=O15),$S$15,IF(AND($B15=M15,OR($C15=N15,$D15=O15)),$S$16+$S$17,IF(OR($B15=M15,AND($C15=N15,$D15=O15)),$S$16,IF(OR($C15=N15,$D15=O15),$S$17))))) -> FALSE | R15: Menü richtig | S15: 3
A16: 45679 | B16: Pizzastrudel | C16: Hackbraten | D16: Püree | E16: Ravioli mit Butter + Parmesan | F16: Pizzaioloschnitzel | G16: Ofenkartoffeln | H16: =IF(ISBLANK($B16),$S$18,IF(AND($B16=E16,$C16=F16,$D16=G16),$S$15,IF(AND($B16=E16,OR($C16=F16,$D16=G16)),$S$16+$S$17,IF(OR($B16=E16,AND($C16=F16,$D16=G16)),$S$16,IF(OR($C16=F16,$D16=G16),$S$17))))) -> FALSE | I16: Carbonara | J16: Truthahnbraten | K16: Püree | L16: =IF(ISBLANK($B16),$S$18,IF(AND($B16=I16,$C16=J16,$D16=K16),$S$15,IF(AND($B16=I16,OR($C16=J16,$D16=K16)),$S$16+$S$17,IF(OR($B16=I16,AND($C16=J16,$D16=K16)),$S$16,IF(OR($C16=J16,$D16=K16),$S$17))))) -> 0.5 | M16: Nudel mit Thunfischsoße | N16: Truthahnschnitzel | O16: Spatzlen | P16: =IF(ISBLANK($B16),$S$18,IF(AND($B16=M16,$C16=N16,$D16=O16),$S$15,IF(AND($B16=M16,OR($C16=N16,$D16=O16)),$S$16+$S$17,IF(OR($B16=M16,AND($C16=N16,$D16=O16)),$S$16,IF(OR($C16=N16,$D16=O16),$S$17))))) -> FALSE | R16: Hauptspeise mit Beilage / Vorspeise richtig | S16: 1
A17: 45680 | B17: Nudel Mammarosa | C17: Schweinsschnitzel | D17: Spatzlen | E17: Lasagne | F17: Wienerschnitzel | G17: Kartoffelsalat | H17: =IF(ISBLANK($B17),$S$18,IF(AND($B17=E17,$C17=F17,$D17=G17),$S$15,IF(AND($B17=E17,OR($C17=F17,$D17=G17)),$S$16+$S$17,IF(OR($B17=E17,AND($C17=F17,$D17=G17)),$S$16,IF(OR($C17=F17,$D17=G17),$S$17))))) -> FALSE | I17: Hirten | J17: Truthahngeschnetzeltes | K17: Reis | L17: =IF(ISBLANK($B17),$S$18,IF(AND($B17=I17,$C17=J17,$D17=K17),$S$15,IF(AND($B17=I17,OR($C17=J17,$D17=K17)),$S$16+$S$17,IF(OR($B17=I17,AND($C17=J17,$D17=K17)),$S$16,IF(OR($C17=J17,$D17=K17),$S$17))))) -> FALSE | M17: Lasagne | N17: Truthahnbraten | O17: Kartoffelgratin | P17: =IF(ISBLANK($B17),$S$18,IF(AND($B17=M17,$C17=N17,$D17=O17),$S$15,IF(AND($B17=M17,OR($C17=N17,$D17=O17)),$S$16+$S$17,IF(OR($B17=M17,AND($C17=N17,$D17=O17)),$S$16,IF(OR($C17=N17,$D17=O17),$S$17))))) -> FALSE | R17: nur Hauptspeise / Beilage richtig | S17: 0.5
A18: 45681 | B18: Ravioli | C18: Knödel | D18: Gulasch | E18: Putanesca | F18: Fisch | G18: Salzkartoffeln | H18: =IF(ISBLANK($B18),$S$18,IF(AND($B18=E18,$C18=F18,$D18=G18),$S$15,IF(AND($B18=E18,OR($C18=F18,$D18=G18)),$S$16+$S$17,IF(OR($B18=E18,AND($C18=F18,$D18=G18)),$S$16,IF(OR($C18=F18,$D18=G18),$S$17))))) -> FALSE | I18: Carbonara | J18: Fisch | K18: Kartoffelsalat | L18: =IF(ISBLANK($B18),$S$18,IF(AND($B18=I18,$C18=J18,$D18=K18),$S$15,IF(AND($B18=I18,OR($C18=J18,$D18=K18)),$S$16+$S$17,IF(OR($B18=I18,AND($C18=J18,$D18=K18)),$S$16,IF(OR($C18=J18,$D18=K18),$S$17))))) -> FALSE | M18: Carbonara | N18: Wienerschnitzel | O18: Kartoffelsalat | P18: =IF(ISBLANK($B18),$S$18,IF(AND($B18=M18,$C18=N18,$D18=O18),$S$15,IF(AND($B18=M18,OR($C18=N18,$D18=O18)),$S$16+$S$17,IF(OR($B18=M18,AND($C18=N18,$D18=O18)),$S$16,IF(OR($C18=N18,$D18=O18),$S$17))))) -> FALSE | R18: Alles falsch | S18: 0
A19: 45684 | B19: Lasagne | C19: Truthahngeschnetzeltes | D19: Kartoffelstampf | E19: Putanesca | F19: Hühnerbrust | G19: Reis | H19: =IF(ISBLANK($B19),$S$18,IF(AND($B19=E19,$C19=F19,$D19=G19),$S$15,IF(AND($B19=E19,OR($C19=F19,$D19=G19)),$S$16+$S$17,IF(OR($B19=E19,AND($C19=F19,$D19=G19)),$S$16,IF(OR($C19=F19,$D19=G19),$S$17))))) -> FALSE | I19: Hirten | J19: Truthahnschnitzel | K19: Ofenkartoffeln | L19: =IF(ISBLANK($B19),$S$18,IF(AND($B19=I19,$C19=J19,$D19=K19),$S$15,IF(AND($B19=I19,OR($C19=J19,$D19=K19)),$S$16+$S$17,IF(OR($B19=I19,AND($C19=J19,$D19=K19)),$S$16,IF(OR($C19=J19,$D19=K19),$S$17))))) -> FALSE | M19: Carbonara | N19: Truthahnschnitzel | O19: Reis | P19: =IF(ISBLANK($B19),$S$18,IF(AND($B19=M19,$C19=N19,$D19=O19),$S$15,IF(AND($B19=M19,OR($C19=N19,$D19=O19)),$S$16+$S$17,IF(OR($B19=M19,AND($C19=N19,$D19=O19)),$S$16,IF(OR($C19=N19,$D19=O19),$S$17))))) -> FALSE
A20: 45685 | B20: Aglio olio | C20: Schweinsschopfbraten | D20: Reis | E20: Nudel mit Käsesoße | F20: Schweinsschopfbraten | G20: Spatzlen | H20: =IF(ISBLANK($B20),$S$18,IF(AND($B20=E20,$C20=F20,$D20=G20),$S$15,IF(AND($B20=E20,OR($C20=F20,$D20=G20)),$S$16+$S$17,IF(OR($B20=E20,AND($C20=F20,$D20=G20)),$S$16,IF(OR($C20=F20,$D20=G20),$S$17))))) -> 0.5 | I20: Spinatspatzlen | J20: Hühnerhaxlen | K20: Pommes | L20: =IF(ISBLANK($B20),$S$18,IF(AND($B20=I20,$C20=J20,$D20=K20),$S$15,IF(AND($B20=I20,OR($C20=J20,$D20=K20)),$S$16+$S$17,IF(OR($B20=I20,AND($C20=J20,$D20=K20)),$S$16,IF(OR($C20=J20,$D20=K20),$S$17))))) -> FALSE | M20: Aglio olio | N20: Hauswurst | O20: Plent | P20: =IF(ISBLANK($B20),$S$18,IF(AND($B20=M20,$C20=N20,$D20=O20),$S$15,IF(AND($B20=M20,OR($C20=N20,$D20=O20)),$S$16+$S$17,IF(OR($B20=M20,AND($C20=N20,$D20=O20)),$S$16,IF(OR($C20=N20,$D20=O20),$S$17))))) -> 1
A21: 45686 | B21: Griesscheiben mit Schinken/Käse und Tomantensoße | C21: Schweinskotelett | D21: Kartoffelgratin | E21: Spinatspatzlen | F21: Gulasch | G21: Plent | H21: =IF(ISBLANK($B21),$S$18,IF(AND($B21=E21,$C21=F21,$D21=G21),$S$15,IF(AND($B21=E21,OR($C21=F21,$D21=G21)),$S$16+$S$17,IF(OR($B21=E21,AND($C21=F21,$D21=G21)),$S$16,IF(OR($C21=F21,$D21=G21),$S$17))))) -> FALSE | I21: Käseknödel | J21: Pizzaioloschnitzel | K21: Ofenkartoffeln | L21: =IF(ISBLANK($B21),$S$18,IF(AND($B21=I21,$C21=J21,$D21=K21),$S$15,IF(AND($B21=I21,OR($C21=J21,$D21=K21)),$S$16+$S$17,IF(OR($B21=I21,AND($C21=J21,$D21=K21)),$S$16,IF(OR($C21=J21,$D21=K21),$S$17))))) -> FALSE | M21: Hirten | N21: Leberkas | O21: Röstkartoffeln | P21: =IF(ISBLANK($B21),$S$18,IF(AND($B21=M21,$C21=N21,$D21=O21),$S$15,IF(AND($B21=M21,OR($C21=N21,$D21=O21)),$S$16+$S$17,IF(OR($B21=M21,AND($C21=N21,$D21=O21)),$S$16,IF(OR($C21=N21,$D21=O21),$S$17))))) -> FALSE
A22: 45687 | B22: Arrabbiata | C22: Hühnerbrust | D22: Kroketten | E22: Carbonara | F22: Leberkas | G22: Röstkartoffeln | H22: =IF(ISBLANK($B22),$S$18,IF(AND($B22=E22,$C22=F22,$D22=G22),$S$15,IF(AND($B22=E22,OR($C22=F22,$D22=G22)),$S$16+$S$17,IF(OR($B22=E22,AND($C22=F22,$D22=G22)),$S$16,IF(OR($C22=F22,$D22=G22),$S$17))))) -> FALSE | I22: Carbonara | J22: Knödel | K22: Gulasch | L22: =IF(ISBLANK($B22),$S$18,IF(AND($B22=I22,$C22=J22,$D22=K22),$S$15,IF(AND($B22=I22,OR($C22=J22,$D22=K22)),$S$16+$S$17,IF(OR($B22=I22,AND($C22=J22,$D22=K22)),$S$16,IF(OR($C22=J22,$D22=K22),$S$17))))) -> FALSE | M22: Carbonara | N22: Truthahnschnitzel | O22: Spatzlen | P22: =IF(ISBLANK($B22),$S$18,IF(AND($B22=M22,$C22=N22,$D22=O22),$S$15,IF(AND($B22=M22,OR($C22=N22,$D22=O22)),$S$16+$S$17,IF(OR($B22=M22,AND($C22=N22,$D22=O22)),$S$16,IF(OR($C22=N22,$D22=O22),$S$17))))) -> FALSE
A23: 45688 | B23: Ravioli mit Käsesoße | C23: Zigeunerschnitzel | D23: Spatzlen | E23: Tortellini mit Schinken-Rahm | F23: Wienerschnitzel | G23: Pommes | H23: =IF(ISBLANK($B23),$S$18,IF(AND($B23=E23,$C23=F23,$D23=G23),$S$15,IF(AND($B23=E23,OR($C23=F23,$D23=G23)),$S$16+$S$17,IF(OR($B23=E23,AND($C23=F23,$D23=G23)),$S$16,IF(OR($C23=F23,$D23=G23),$S$17))))) -> FALSE | I23: Käseknödel | J23: Wienerschnitzel | K23: Pommes | L23: =IF(ISBLANK($B23),$S$18,IF(AND($B23=I23,$C23=J23,$D23=K23),$S$15,IF(AND($B23=I23,OR($C23=J23,$D23=K23)),$S$16+$S$17,IF(OR($B23=I23,AND($C23=J23,$D23=K23)),$S$16,IF(OR($C23=J23,$D23=K23),$S$17))))) -> FALSE | M23: Hirten | N23: Wienerschnitzel | O23: Kartoffelsalat | P23: =IF(ISBLANK($B23),$S$18,IF(AND($B23=M23,$C23=N23,$D23=O23),$S$15,IF(AND($B23=M23,OR($C23=N23,$D23=O23)),$S$16+$S$17,IF(OR($B23=M23,AND($C23=N23,$D23=O23)),$S$16,IF(OR($C23=N23,$D23=O23),$S$17))))) -> FALSE
A24: 45691 | B24: Hirten | C24: Truthahnbraten | D24: Reis | E24: Hirten | F24: Fleischkrapfln | G24: Püree | H24: =IF(ISBLANK($B24),$S$18,IF(AND($B24=E24,$C24=F24,$D24=G24),$S$15,IF(AND($B24=E24,OR($C24=F24,$D24=G24)),$S$16+$S$17,IF(OR($B24=E24,AND($C24=F24,$D24=G24)),$S$16,IF(OR($C24=F24,$D24=G24),$S$17))))) -> 1 | I24: Hirten | J24: Truthahngeschnetzeltes | K24: Püree | L24: =IF(ISBLANK($B24),$S$18,IF(AND($B24=I24,$C24=J24,$D24=K24),$S$15,IF(AND($B24=I24,OR($C24=J24,$D24=K24)),$S$16+$S$17,IF(OR($B24=I24,AND($C24=J24,$D24=K24)),$S$16,IF(OR($C24=J24,$D24=K24),$S$17))))) -> 1 | M24: Hirten | N24: Truthahnschnitzel | O24: Reis | P24: =IF(ISBLANK($B24),$S$18,IF(AND($B24=M24,$C24=N24,$D24=O24),$S$15,IF(AND($B24=M24,OR($C24=N24,$D24=O24)),$S$16+$S$17,IF(OR($B24=M24,AND($C24=N24,$D24=O24)),$S$16,IF(OR($C24=N24,$D24=O24),$S$17))))) -> 1.5
A25: 45692 | B25: Spinatspatzlen | C25: Schweinsgulasch | D25: Püree | E25: Pizzastrudel | F25: Hühnerhaxlen | G25: Ofenkartoffeln | H25: =IF(ISBLANK($B25),$S$18,IF(AND($B25=E25,$C25=F25,$D25=G25),$S$15,IF(AND($B25=E25,OR($C25=F25,$D25=G25)),$S$16+$S$17,IF(OR($B25=E25,AND($C25=F25,$D25=G25)),$S$16,IF(OR($C25=F25,$D25=G25),$S$17))))) -> FALSE | I25: Käseknödel | J25: Pizzaioloschnitzel | K25: Ofenkartoffeln | L25: =IF(ISBLANK($B25),$S$18,IF(AND($B25=I25,$C25=J25,$D25=K25),$S$15,IF(AND($B25=I25,OR($C25=J25,$D25=K25)),$S$16+$S$17,IF(OR($B25=I25,AND($C25=J25,$D25=K25)),$S$16,IF(OR($C25=J25,$D25=K25),$S$17))))) -> FALSE | M25: Pizza | N25: Schweinsfilet | O25: Spatzlen | P25: =IF(ISBLANK($B25),$S$18,IF(AND($B25=M25,$C25=N25,$D25=O25),$S$15,IF(AND($B25=M25,OR($C25=N25,$D25=O25)),$S$16+$S$17,IF(OR($B25=M25,AND($C25=N25,$D25=O25)),$S$16,IF(OR($C25=N25,$D25=O25),$S$17))))) -> FALSE
A26: 45693 | B26: Nudel mit Thunfischsoße | C26: Wienerschnitzel | D26: Pommes | E26: Carbonara | F26: Pizzaioloschnitzel | G26: Pommes | H26: =IF(ISBLANK($B26),$S$18,IF(AND($B26=E26,$C26=F26,$D26=G26),$S$15,IF(AND($B26=E26,OR($C26=F26,$D26=G26)),$S$16+$S$17,IF(OR($B26=E26,AND($C26=F26,$D26=G26)),$S$16,IF(OR($C26=F26,$D26=G26),$S$17))))) -> 0.5 | I26: Nudel mit Thunfischsoße | J26: Leberkas | K26: Pommes | L26: =IF(ISBLANK($B26),$S$18,IF(AND($B26=I26,$C26=J26,$D26=K26),$S$15,IF(AND($B26=I26,OR($C26=J26,$D26=K26)),$S$16+$S$17,IF(OR($B26=I26,AND($C26=J26,$D26=K26)),$S$16,IF(OR($C26=J26,$D26=K26),$S$17))))) -> 1.5 | M26: Putanesca | N26: Truthahnschnitzel | O26: Ofenkartoffeln | P26: =IF(ISBLANK($B26),$S$18,IF(AND($B26=M26,$C26=N26,$D26=O26),$S$15,IF(AND($B26=M26,OR($C26=N26,$D26=O26)),$S$16+$S$17,IF(OR($B26=M26,AND($C26=N26,$D26=O26)),$S$16,IF(OR($C26=N26,$D26=O26),$S$17))))) -> FALSE
A27: 45694 | B27: Carbonara | C27: Hühnerhaxlen | D27: Pommes | E27: Käseknödel | F27: Sparerips | G27: Ofenkartoffeln | H27: =IF(ISBLANK($B27),$S$18,IF(AND($B27=E27,$C27=F27,$D27=G27),$S$15,IF(AND($B27=E27,OR($C27=F27,$D27=G27)),$S$16+$S$17,IF(OR($B27=E27,AND($C27=F27,$D27=G27)),$S$16,IF(OR($C27=F27,$D27=G27),$S$17))))) -> FALSE | I27: Käseknödel | J27: Pizzaioloschnitzel | K27: Ofenkartoffeln | L27: =IF(ISBLANK($B27),$S$18,IF(AND($B27=I27,$C27=J27,$D27=K27),$S$15,IF(AND($B27=I27,OR($C27=J27,$D27=K27)),$S$16+$S$17,IF(OR($B27=I27,AND($C27=J27,$D27=K27)),$S$16,IF(OR($C27=J27,$D27=K27),$S$17))))) -> FALSE | M27: Carbonara | N27: Hauswurst | O27: Plent | P27: =IF(ISBLANK($B27),$S$18,IF(AND($B27=M27,$C27=N27,$D27=O27),$S$15,IF(AND($B27=M27,OR($C27=N27,$D27=O27)),$S$16+$S$17,IF(OR($B27=M27,AND($C27=N27,$D27=O27)),$S$16,IF(OR($C27=N27,$D27=O27),$S$17))))) -> 1
A28: 45695 | B28: Käseknödel | C28: Chilli con carne | D28: Reis | E28: Plentauflauf | F28: Vitello tonnato | G28: Salzkartoffeln | H28: =IF(ISBLANK($B28),$S$18,IF(AND($B28=E28,$C28=F28,$D28=G28),$S$15,IF(AND($B28=E28,OR($C28=F28,$D28=G28)),$S$16+$S$17,IF(OR($B28=E28,AND($C28=F28,$D28=G28)),$S$16,IF(OR($C28=F28,$D28=G28),$S$17))))) -> FALSE | I28: Spinatknödel | J28: Fisch | K28: Salzkartoffeln | L28: =IF(ISBLANK($B28),$S$18,IF(AND($B28=I28,$C28=J28,$D28=K28),$S$15,IF(AND($B28=I28,OR($C28=J28,$D28=K28)),$S$16+$S$17,IF(OR($B28=I28,AND($C28=J28,$D28=K28)),$S$16,IF(OR($C28=J28,$D28=K28),$S$17))))) -> FALSE | M28: Pizzastrudel | N28: Schweinsfilet | O28: Kartoffelgratin | P28: =IF(ISBLANK($B28),$S$18,IF(AND($B28=M28,$C28=N28,$D28=O28),$S$15,IF(AND($B28=M28,OR($C28=N28,$D28=O28)),$S$16+$S$17,IF(OR($B28=M28,AND($C28=N28,$D28=O28)),$S$16,IF(OR($C28=N28,$D28=O28),$S$17))))) -> FALSE
A29: 45698 | B29: Nudel Mammarosa | C29: Truthahnschnitzel | D29: Ofenkartoffeln | E29: - | F29: - | G29: - | H29: =IF(ISBLANK($B29),$S$18,IF(AND($B29=E29,$C29=F29,$D29=G29),$S$15,IF(AND($B29=E29,OR($C29=F29,$D29=G29)),$S$16+$S$17,IF(OR($B29=E29,AND($C29=F29,$D29=G29)),$S$16,IF(OR($C29=F29,$D29=G29),$S$17))))) -> FALSE | I29: Putanesca | J29: Leberkas | K29: Ofenkartoffeln | L29: =IF(ISBLANK($B29),$S$18,IF(AND($B29=I29,$C29=J29,$D29=K29),$S$15,IF(AND($B29=I29,OR($C29=J29,$D29=K29)),$S$16+$S$17,IF(OR($B29=I29,AND($C29=J29,$D29=K29)),$S$16,IF(OR($C29=J29,$D29=K29),$S$17))))) -> 0.5 | M29: Lasagne | N29: Truthahnschnitzel | O29: Reis | P29: =IF(ISBLANK($B29),$S$18,IF(AND($B29=M29,$C29=N29,$D29=O29),$S$15,IF(AND($B29=M29,OR($C29=N29,$D29=O29)),$S$16+$S$17,IF(OR($B29=M29,AND($C29=N29,$D29=O29)),$S$16,IF(OR($C29=N29,$D29=O29),$S$17))))) -> 0.5
A30: 45699 | B30: Gnocchi mit Ragu | C30: Schnitzel mit Champignonsauce | D30: Reis | E30: Nudel mit Käsesoße | F30: Gekochtes Rindfleisch | G30: Salzkartoffeln | H30: =IF(ISBLANK($B30),$S$18,IF(AND($B30=E30,$C30=F30,$D30=G30),$S$15,IF(AND($B30=E30,OR($C30=F30,$D30=G30)),$S$16+$S$17,IF(OR($B30=E30,AND($C30=F30,$D30=G30)),$S$16,IF(OR($C30=F30,$D30=G30),$S$17))))) -> FALSE | I30: Spinatspatzlen | J30: Schweinsbraten | K30: Reis | L30: =IF(ISBLANK($B30),$S$18,IF(AND($B30=I30,$C30=J30,$D30=K30),$S$15,IF(AND($B30=I30,OR($C30=J30,$D30=K30)),$S$16+$S$17,IF(OR($B30=I30,AND($C30=J30,$D30=K30)),$S$16,IF(OR($C30=J30,$D30=K30),$S$17))))) -> 0.5 | M30: Putanesca | N30: Schweinsfilet | O30: Spatzlen | P30: =IF(ISBLANK($B30),$S$18,IF(AND($B30=M30,$C30=N30,$D30=O30),$S$15,IF(AND($B30=M30,OR($C30=N30,$D30=O30)),$S$16+$S$17,IF(OR($B30=M30,AND($C30=N30,$D30=O30)),$S$16,IF(OR($C30=N30,$D30=O30),$S$17))))) -> FALSE
... A177: 45937 | B177: Lasagne | C177: Hühnerbrust | D177: Kroketten | E177: Tortellini mit Schinken-Rahm | F177: Wienerschnitzel | G177: Kartoffelsalat | H177: =IF(ISBLANK($B177),$S$18,IF(AND($B177=E177,$C177=F177,$D177=G177),$S$15,IF(AND($B177=E177,OR($C177=F177,$D177=G177)),$S$16+$S$17,IF(OR($B177=E177,AND($C177=F177,$D177=G177)),$S$16,IF(OR($C177=F177,$D177=G177),$S$17))))) -> FALSE | I177: Carbonara | J177: Leberkas | K177: Röstkartoffeln | L177: =IF(ISBLANK($B177),$S$18,IF(AND($B177=I177,$C177=J177,$D177=K177),$S$15,IF(AND($B177=I177,OR($C177=J177,$D177=K177)),$S$16+$S$17,IF(OR($B177=I177,AND($C177=J177,$D177=K177)),$S$16,IF(OR($C177=J177,$D177=K177),$S$17))))) -> FALSE | M177: Spinatspatzlen | N177: Truthahnschnitzel | O177: Ofenkartoffeln | P177: =IF(ISBLANK($B177),$S$18,IF(AND($B177=M177,$C177=N177,$D177=O177),$S$15,IF(AND($B177=M177,OR($C177=N177,$D177=O177)),$S$16+$S$17,IF(OR($B177=M177,AND($C177=N177,$D177=O177)),$S$16,IF(OR($C177=N177,$D177=O177),$S$17))))) -> FALSE
A178: 45938 | B178: Aglio olio | C178: Cordon Bleu | D178: Kartoffelsalat / Pommes | E178: Nudel mit Käsesoße | F178: Currywurst | G178: Kartoffelsalat / Pommes | H178: =IF(ISBLANK($B178),$S$18,IF(AND($B178=E178,$C178=F178,$D178=G178),$S$15,IF(AND($B178=E178,OR($C178=F178,$D178=G178)),$S$16+$S$17,IF(OR($B178=E178,AND($C178=F178,$D178=G178)),$S$16,IF(OR($C178=F178,$D178=G178),$S$17))))) -> 0.5 | I178: Spinatspatzlen | J178: Wienerschnitzel | K178: Kartoffelsalat / Pommes | L178: =IF(ISBLANK($B178),$S$18,IF(AND($B178=I178,$C178=J178,$D178=K178),$S$15,IF(AND($B178=I178,OR($C178=J178,$D178=K178)),$S$16+$S$17,IF(OR($B178=I178,AND($C178=J178,$D178=K178)),$S$16,IF(OR($C178=J178,$D178=K178),$S$17))))) -> 0.5 | M178: Aglio olio | N178: Leberkas | O178: Röstkartoffeln | P178: =IF(ISBLANK($B178),$S$18,IF(AND($B178=M178,$C178=N178,$D178=O178),$S$15,IF(AND($B178=M178,OR($C178=N178,$D178=O178)),$S$16+$S$17,IF(OR($B178=M178,AND($C178=N178,$D178=O178)),$S$16,IF(OR($C178=N178,$D178=O178),$S$17))))) -> 1 | Q178: x
A179: 45939 | B179: Tortellini mit Schinken-Rahm | C179: Schweinsschopf | D179: Ofenkartoffeln | E179: Spinatknödel | F179: Schweinsschopfbraten | G179: Spatzlen | H179: =IF(ISBLANK($B179),$S$18,IF(AND($B179=E179,$C179=F179,$D179=G179),$S$15,IF(AND($B179=E179,OR($C179=F179,$D179=G179)),$S$16+$S$17,IF(OR($B179=E179,AND($C179=F179,$D179=G179)),$S$16,IF(OR($C179=F179,$D179=G179),$S$17))))) -> FALSE | I179: Schlutzer | J179: Gulasch | K179: Spatzlen | L179: 3 | M179: Spinatspatzlen | N179: Schweinsfilet | O179: Kartoffelgratin | P179: =IF(ISBLANK($B179),$S$18,IF(AND($B179=M179,$C179=N179,$D179=O179),$S$15,IF(AND($B179=M179,OR($C179=N179,$D179=O179)),$S$16+$S$17,IF(OR($B179=M179,AND($C179=N179,$D179=O179)),$S$16,IF(OR($C179=N179,$D179=O179),$S$17))))) -> FALSE
A180: 45940 | B180: Nudel mit Käsesoße | C180: Gulasch | D180: Reis | E180: Spinatspatzlen | F180: Gulasch | G180: Plent | H180: =IF(ISBLANK($B180),$S$18,IF(AND($B180=E180,$C180=F180,$D180=G180),$S$15,IF(AND($B180=E180,OR($C180=F180,$D180=G180)),$S$16+$S$17,IF(OR($B180=E180,AND($C180=F180,$D180=G180)),$S$16,IF(OR($C180=F180,$D180=G180),$S$17))))) -> 0.5 | I180: Carbonara | J180: Leberkas | K180: Röstkartoffeln | L180: =IF(ISBLANK($B180),$S$18,IF(AND($B180=I180,$C180=J180,$D180=K180),$S$15,IF(AND($B180=I180,OR($C180=J180,$D180=K180)),$S$16+$S$17,IF(OR($B180=I180,AND($C180=J180,$D180=K180)),$S$16,IF(OR($C180=J180,$D180=K180),$S$17))))) -> FALSE | M180: Nudel mit Käsesoße | N180: Truthahngeschnetzeltes | O180: Püree | P180: =IF(ISBLANK($B180),$S$18,IF(AND($B180=M180,$C180=N180,$D180=O180),$S$15,IF(AND($B180=M180,OR($C180=N180,$D180=O180)),$S$16+$S$17,IF(OR($B180=M180,AND($C180=N180,$D180=O180)),$S$16,IF(OR($C180=N180,$D180=O180),$S$17))))) -> 1
A181: 45943 | B181: Hirten | C181: Schweinsschnitzel mit Kräuterrahmsoße | D181: Reis | E181: Nudel mit Ragu | F181: Truthahngeschnetzeltes | G181: Reis | H181: =IF(ISBLANK($B181),$S$18,IF(AND($B181=E181,$C181=F181,$D181=G181),$S$15,IF(AND($B181=E181,OR($C181=F181,$D181=G181)),$S$16+$S$17,IF(OR($B181=E181,AND($C181=F181,$D181=G181)),$S$16,IF(OR($C181=F181,$D181=G181),$S$17))))) -> 0.5 | I181: Amatriciana | J181: Schweinsschnitzel mit Kräuterrahmsoße | K181: Kartoffelgratin | L181: =IF(ISBLANK($B181),$S$18,IF(AND($B181=I181,$C181=J181,$D181=K181),$S$15,IF(AND($B181=I181,OR($C181=J181,$D181=K181)),$S$16+$S$17,IF(OR($B181=I181,AND($C181=J181,$D181=K181)),$S$16,IF(OR($C181=J181,$D181=K181),$S$17))))) -> 0.5 | M181: Arrabbiata | N181: Schweinsschnitzel mit Kräuterrahmsoße | O181: Spatzlen | P181: =IF(ISBLANK($B181),$S$18,IF(AND($B181=M181,$C181=N181,$D181=O181),$S$15,IF(AND($B181=M181,OR($C181=N181,$D181=O181)),$S$16+$S$17,IF(OR($B181=M181,AND($C181=N181,$D181=O181)),$S$16,IF(OR($C181=N181,$D181=O181),$S$17))))) -> 0.5 | Q181: x
A182: 45944 | B182: Arrabbiata | C182: Truthahnbraten | D182: Spatzlen | E182: Putanesca | F182: Currywurst | G182: Pommes | H182: =IF(ISBLANK($B182),$S$18,IF(AND($B182=E182,$C182=F182,$D182=G182),$S$15,IF(AND($B182=E182,OR($C182=F182,$D182=G182)),$S$16+$S$17,IF(OR($B182=E182,AND($C182=F182,$D182=G182)),$S$16,IF(OR($C182=F182,$D182=G182),$S$17))))) -> FALSE | I182: Carbonara | J182: Leberkas | K182: Röstkartoffeln | L182: =IF(ISBLANK($B182),$S$18,IF(AND($B182=I182,$C182=J182,$D182=K182),$S$15,IF(AND($B182=I182,OR($C182=J182,$D182=K182)),$S$16+$S$17,IF(OR($B182=I182,AND($C182=J182,$D182=K182)),$S$16,IF(OR($C182=J182,$D182=K182),$S$17))))) -> FALSE | M182: Spinatspatzlen | N182: Truthahngeschnetzeltes | O182: Püree | P182: =IF(ISBLANK($B182),$S$18,IF(AND($B182=M182,$C182=N182,$D182=O182),$S$15,IF(AND($B182=M182,OR($C182=N182,$D182=O182)),$S$16+$S$17,IF(OR($B182=M182,AND($C182=N182,$D182=O182)),$S$16,IF(OR($C182=N182,$D182=O182),$S$17))))) -> FALSE
A183: 45945 | B183: Plentauflauf | C183: Leberkas | D183: Pommes | E183: Schlutzer | F183: Hühnerhaxlen | G183: Ofenkartoffeln | H183: =IF(ISBLANK($B183),$S$18,IF(AND($B183=E183,$C183=F183,$D183=G183),$S$15,IF(AND($B183=E183,OR($C183=F183,$D183=G183)),$S$16+$S$17,IF(OR($B183=E183,AND($C183=F183,$D183=G183)),$S$16,IF(OR($C183=F183,$D183=G183),$S$17))))) -> FALSE | I183: Spinatspatzlen | J183: Currywurst | K183: Pommes | L183: =IF(ISBLANK($B183),$S$18,IF(AND($B183=I183,$C183=J183,$D183=K183),$S$15,IF(AND($B183=I183,OR($C183=J183,$D183=K183)),$S$16+$S$17,IF(OR($B183=I183,AND($C183=J183,$D183=K183)),$S$16,IF(OR($C183=J183,$D183=K183),$S$17))))) -> 0.5 | M183: Spinatknödel mit Käsesoße | N183: Wienerschnitzel | O183: Pommes | P183: =IF(ISBLANK($B183),$S$18,IF(AND($B183=M183,$C183=N183,$D183=O183),$S$15,IF(AND($B183=M183,OR($C183=N183,$D183=O183)),$S$16+$S$17,IF(OR($B183=M183,AND($C183=N183,$D183=O183)),$S$16,IF(OR($C183=N183,$D183=O183),$S$17))))) -> 0.5
A184: 45946 | B184: Aglio olio | C184: Chilli con carne | D184: Reis | E184: Aglio olio | F184: Chilli con carne | G184: Reis | H184: =IF(ISBLANK($B184),$S$18,IF(AND($B184=E184,$C184=F184,$D184=G184),$S$15,IF(AND($B184=E184,OR($C184=F184,$D184=G184)),$S$16+$S$17,IF(OR($B184=E184,AND($C184=F184,$D184=G184)),$S$16,IF(OR($C184=F184,$D184=G184),$S$17))))) -> 3 | I184: Aglio olio | J184: Chilli con carne | K184: Reis | L184: =IF(ISBLANK($B184),$S$18,IF(AND($B184=I184,$C184=J184,$D184=K184),$S$15,IF(AND($B184=I184,OR($C184=J184,$D184=K184)),$S$16+$S$17,IF(OR($B184=I184,AND($C184=J184,$D184=K184)),$S$16,IF(OR($C184=J184,$D184=K184),$S$17))))) -> 3 | M184: Aglio olio | N184: Chilli con carne | O184: Reis | P184: =IF(ISBLANK($B184),$S$18,IF(AND($B184=M184,$C184=N184,$D184=O184),$S$15,IF(AND($B184=M184,OR($C184=N184,$D184=O184)),$S$16+$S$17,IF(OR($B184=M184,AND($C184=N184,$D184=O184)),$S$16,IF(OR($C184=N184,$D184=O184),$S$17))))) -> 3
A185: 45947 | B185: Schlutzer | C185: Schweinsschnitzel | D185: Ofenkartoffeln | E185: - | F185: - | G185: - | H185: =IF(ISBLANK($B185),$S$18,IF(AND($B185=E185,$C185=F185,$D185=G185),$S$15,IF(AND($B185=E185,OR($C185=F185,$D185=G185)),$S$16+$S$17,IF(OR($B185=E185,AND($C185=F185,$D185=G185)),$S$16,IF(OR($C185=F185,$D185=G185),$S$17))))) -> FALSE | I185: Nudel mit Meeresfrüchte | J185: Hühnerhaxlen | K185: Ofenkartoffeln | L185: =IF(ISBLANK($B185),$S$18,IF(AND($B185=I185,$C185=J185,$D185=K185),$S$15,IF(AND($B185=I185,OR($C185=J185,$D185=K185)),$S$16+$S$17,IF(OR($B185=I185,AND($C185=J185,$D185=K185)),$S$16,IF(OR($C185=J185,$D185=K185),$S$17))))) -> 0.5 | M185: Spinatspatzlen | N185: Schweinsfilet | O185: Kartoffelgratin | P185: =IF(ISBLANK($B185),$S$18,IF(AND($B185=M185,$C185=N185,$D185=O185),$S$15,IF(AND($B185=M185,OR($C185=N185,$D185=O185)),$S$16+$S$17,IF(OR($B185=M185,AND($C185=N185,$D185=O185)),$S$16,IF(OR($C185=N185,$D185=O185),$S$17))))) -> FALSE
A186: 45950 | B186: Amatriciana | C186: Schweinsgulasch | D186: Püree | E186: Nudel mit Thunfischsoße | F186: Champignonschnitzel | G186: Püree | H186: =IF(ISBLANK($B186),$S$18,IF(AND($B186=E186,$C186=F186,$D186=G186),$S$15,IF(AND($B186=E186,OR($C186=F186,$D186=G186)),$S$16+$S$17,IF(OR($B186=E186,AND($C186=F186,$D186=G186)),$S$16,IF(OR($C186=F186,$D186=G186),$S$17))))) -> 0.5 | I186: Amatriciana | J186: Truthahnschnitzel | K186: Pommes | L186: =IF(ISBLANK($B186),$S$18,IF(AND($B186=I186,$C186=J186,$D186=K186),$S$15,IF(AND($B186=I186,OR($C186=J186,$D186=K186)),$S$16+$S$17,IF(OR($B186=I186,AND($C186=J186,$D186=K186)),$S$16,IF(OR($C186=J186,$D186=K186),$S$17))))) -> 1 | M186: Arrabbiata | N186: Champignonschnitzel | O186: Reis | P186: =IF(ISBLANK($B186),$S$18,IF(AND($B186=M186,$C186=N186,$D186=O186),$S$15,IF(AND($B186=M186,OR($C186=N186,$D186=O186)),$S$16+$S$17,IF(OR($B186=M186,AND($C186=N186,$D186=O186)),$S$16,IF(OR($C186=N186,$D186=O186),$S$17))))) -> FALSE
A187: 45951 | B187: Spinatspatzlen | C187: Hühnerhaxlen | D187: Pommes | E187: Spinatspatzlen | F187: Truthahnschnitzel | G187: Reis | H187: =IF(ISBLANK($B187),$S$18,IF(AND($B187=E187,$C187=F187,$D187=G187),$S$15,IF(AND($B187=E187,OR($C187=F187,$D187=G187)),$S$16+$S$17,IF(OR($B187=E187,AND($C187=F187,$D187=G187)),$S$16,IF(OR($C187=F187,$D187=G187),$S$17))))) -> 1 | I187: Tortellini mit Schinken-Rahm | J187: Truthahngeschnetzeltes | K187: Reis | L187: =IF(ISBLANK($B187),$S$18,IF(AND($B187=I187,$C187=J187,$D187=K187),$S$15,IF(AND($B187=I187,OR($C187=J187,$D187=K187)),$S$16+$S$17,IF(OR($B187=I187,AND($C187=J187,$D187=K187)),$S$16,IF(OR($C187=J187,$D187=K187),$S$17))))) -> FALSE | M187: Pizzastrudel | N187: Truthahngeschnetzeltes | O187: Ofenkartoffeln | P187: =IF(ISBLANK($B187),$S$18,IF(AND($B187=M187,$C187=N187,$D187=O187),$S$15,IF(AND($B187=M187,OR($C187=N187,$D187=O187)),$S$16+$S$17,IF(OR($B187=M187,AND($C187=N187,$D187=O187)),$S$16,IF(OR($C187=N187,$D187=O187),$S$17))))) -> FALSE
...

Sheet 2026
A1: Tippspiel Essen Wies | E1: Andreas | I1: Johannes | M1: Noah | Q1: Johannes Paul III
A2: Regelwerk siehe entsprechendes Tabellenblatt | E2: Punkte | H2: =SUM(H9:H256) -> 44.5 | I2: Punkte | L2: =SUM(L9:L256) -> 45.5 | M2: Punkte | P2: =SUM(P9:P256) -> 41.5 | Q2: Punkte | T2: =SUM(T9:T256) -> 41
E3: Punkteausbeute | H3: =(100/(3*COUNTIFS($B$9:$B$256,"<>",$B$9:$B$256,"<>frei")))*H2 -> 8.2407407 | I3: Punkteausbeute | L3: =(100/(3*COUNTIFS($B$9:$B$256,"<>",$B$9:$B$256,"<>frei")))*L2 -> 8.4259259 | M3: Punkteausbeute | P3: =(100/(3*COUNTIFS($B$9:$B$256,"<>",$B$9:$B$256,"<>frei")))*P2 -> 7.6851852 | Q3: Punkteausbeute | T3: =(100/(3*COUNTIFS($B$9:$B$256,"<>",$B$9:$B$256,"<>frei")))*T2 -> 7.5925926
E4: Durchschnittspunkte pro Kalenderwoche | H4: =H2/_xlfn.ISOWEEKNUM(TODAY()) -> 1.0853659 | I4: Durchschnittspunkte pro Kalenderwoche | L4: =L2/_xlfn.ISOWEEKNUM(TODAY()) -> 1.1097561 | M4: Durchschnittspunkte pro Kalenderwoche | P4: =P2/_xlfn.ISOWEEKNUM(TODAY()) -> 1.0121951 | Q4: Durchschnittspunkte pro Kalenderwoche | T4: =T2/_xlfn.ISOWEEKNUM(TODAY()) -> 1
E5: Alles Falsch | H5: =COUNTIF(H9:H256,"Falsch") -> 135 | I5: Alles Falsch | L5: =COUNTIF(L9:L256,"Falsch") -> 134 | M5: Alles Falsch | P5: =COUNTIF(P9:P256,"Falsch") -> 142 | Q5: Alles Falsch | T5: =COUNTIF(T9:T256,"Falsch") -> 144
H6: =(100/COUNTIFS($B$9:$B$256,"<>",$B$9:$B$256,"<>frei"))*H5 -> 75 | L6: =(100/COUNTIFS($B$9:$B$256,"<>",$B$9:$B$256,"<>frei"))*L5 -> 74.444444 | P6: =(100/COUNTIFS($B$9:$B$256,"<>",$B$9:$B$256,"<>frei"))*P5 -> 78.888889 | T6: =(100/COUNTIFS($B$9:$B$256,"<>",$B$9:$B$256,"<>frei"))*T5 -> 80
E7: Alles Richtig | H7: =COUNTIF(H9:H256,"3") -> 0 | I7: Alles Richtig | L7: =COUNTIF(L9:L256,"3") -> 1 | M7: Alles Richtig | P7: =COUNTIF(P9:P256,"3") -> 1 | Q7: Alles Richtig | T7: =COUNTIF(T9:T256,"3") -> 2
A8: Tag | B8: Vorspeise | C8: Hauptspeise | D8: Beilage | E8: Vorspeise | F8: Hauptspeise | G8: Beilage | H8: Punkte | I8: Vorspeise | J8: Hauptspeise | K8: Beilage | L8: Punkte | M8: Vorspeise | N8: Hauptspeise | O8: Beilage | P8: Punkte | Q8: Vorspeise | R8: Hauptspeise | S8: Beilage | T8: Punkte
